<robot
  name="dog_urdf">
  <link
    name="base_link">
    <inertial>
      <origin
        xyz="-0.0023050784941594 0.000787651476062384 0.00938957145256008"
        rpy="0 0 0" />
      <mass
        value="5.31392098334851" />
      <inertia
        ixx="0.00874227594683645"
        ixy="2.08524954779002E-06"
        ixz="3.91022569694446E-07"
        iyy="0.00891593607580117"
        iyz="4.33240016827745E-07"
        izz="0.00902773976647324" />
    </inertial>
    <visual>
      <origin
        xyz="0 0 0"
        rpy="0 0 0" />
      <geometry>
        <mesh
          filename="package://dog_urdf/meshes/base_link.STL" />
      </geometry>
      <material
        name="body_material">
        <color
          rgba="0.792156862745098 0.819607843137255 0.933333333333333 1" />
      </material>
    </visual>
    <collision>
      <origin
        xyz="0 0 0.01"
        rpy="0 0 0" />
      <geometry>
        <box size="0.30 0.12 0.08" />
      </geometry>
    </collision>
  </link>
  <link
    name="FL_hip">
    <inertial>
      <origin
        xyz="0.0586708362293079 0.00174712967469963 -7.8795421490147E-05"
        rpy="0 0 0" />
      <mass
        value="0.230146330118093" />
      <inertia
        ixx="0.000145714252035461"
        ixy="-1.35495978782419E-07"
        ixz="-3.33188023713209E-07"
        iyy="0.000246238315405917"
        iyz="-2.59322004393892E-08"
        izz="0.000128357183764396" />
    </inertial>
    <visual>
      <origin
        xyz="0 0 0"
        rpy="0 0 0" />
      <geometry>
        <mesh
          filename="package://dog_urdf/meshes/FL_hip.STL" />
      </geometry>
      <material
        name="body_material">
        <color
          rgba="0.792156862745098 0.819607843137255 0.933333333333333 1" />
      </material>
    </visual>
    <collision>
      <origin
        xyz="0.03 0 0"
        rpy="0 1.5708 0" />
      <geometry>
        <cylinder radius="0.025" length="0.06" />
      </geometry>
    </collision>
  </link>
  <joint
    name="FL_hip_joint"
    type="revolute">
    <origin
      xyz="0.1426 0.046487 0"
      rpy="0 0 0" />
    <parent
      link="base_link" />
    <child
      link="FL_hip" />
    <axis
      xyz="1 0 0" />
    <dynamics damping="0.0" friction="0.0"/>
    <limit
        lower="-0.5"
        upper="0.5"
        effort="40"
        velocity="12" />
  </joint>
  <link
    name="FL_thigh">
    <inertial>
      <origin
        xyz="3.96131492397256E-06 0.0530216135226285 -0.0127549994713949"
        rpy="0 0 0" />
      <mass
        value="0.978596689781306" />
      <inertia
        ixx="0.000999824561330957"
        ixy="-2.53313934487292E-07"
        ixz="-6.77603647230633E-07"
        iyy="0.00143499535697583"
        iyz="-1.56862596470955E-05"
        izz="0.000773011521838463" />
    </inertial>
    <visual>
      <origin
        xyz="0 0 0"
        rpy="0 0 0" />
      <geometry>
        <mesh
          filename="package://dog_urdf/meshes/FL_thigh.STL" />
      </geometry>
      <material
        name="body_material">
        <color
          rgba="0.792156862745098 0.819607843137255 0.933333333333333 1" />
      </material>
    </visual>
    <collision>
      <origin
        xyz="0 0.055 -0.09"
        rpy="0 0.35 0" />
      <geometry>
        <cylinder radius="0.03" length="0.18" />
      </geometry>
    </collision>
  </link>
  <joint
    name="FL_thigh_joint"
    type="revolute">
    <origin
      xyz="0.0645133382530963 0.0204632257018415 0"
      rpy="0 0 0" />
    <parent
      link="FL_hip" />
    <child
      link="FL_thigh" />
    <axis
      xyz="0 1 0" />
    <dynamics damping="0.0" friction="0.0"/>
    <limit
        lower="-1.90"
        upper="1.92"
        effort="55"
        velocity="14" />
  </joint>
  <link
    name="FL_calf">
    <inertial>
      <origin
        xyz="3.05292895786818E-05 -9.36885009469417E-05 -0.0670819670227258"
        rpy="0 0 0" />
      <mass
        value="0.174854579981966" />
      <inertia
        ixx="0.000347514079997905"
        ixy="9.59597363222395E-08"
        ixz="-3.10971733237804E-07"
        iyy="0.000363518361270919"
        iyz="-1.28911233952037E-06"
        izz="2.29103709558954E-05" />
    </inertial>
    <visual>
      <origin
        xyz="0 0 0"
        rpy="0 0 0" />
      <geometry>
        <mesh
          filename="package://dog_urdf/meshes/FL_calf.STL" />
      </geometry>
      <material
        name="body_material">
        <color
          rgba="0.792156862745098 0.819607843137255 0.933333333333333 1" />
      </material>
    </visual>
    <collision>
      <origin
        xyz="0 0 -0.09"
        rpy="0 0 0" />
      <geometry>
        <cylinder radius="0.022" length="0.18" />
      </geometry>
    </collision>
  </link>
  <joint
    name="FL_calf_joint"
    type="revolute">
    <origin
      xyz="-1.42640517181852E-05 0.0922000000000003 -0.179998920942403"
      rpy="0 0 0" />
    <parent
      link="FL_thigh" />
    <child
      link="FL_calf" />
    <axis
      xyz="0 1 0" />
    <dynamics damping="0.0" friction="0.0"/>
    <limit
        lower="-2.80"
        upper="-0.28"
        effort="55"
        velocity="14" />
  </joint>
  <link
    name="FL_foot">
    <inertial>
      <origin
        xyz="3.03153155772895E-08 3.64375196681976E-13 0.00474142838422875"
        rpy="0 0 0" />
      <mass
        value="0.0179075406761494" />
      <inertia
        ixx="1.99645361745723E-06"
        ixy="-1.49762941280545E-11"
        ixz="-6.09491739163073E-12"
        iyy="3.20707388303332E-06"
        iyz="1.94067313721918E-16"
        izz="2.94967483562761E-06" />
    </inertial>
    <visual>
      <origin
        xyz="0 0 0"
        rpy="0 0 0" />
      <geometry>
        <mesh
          filename="package://dog_urdf/meshes/FL_foot.STL" />
      </geometry>
      <material
        name="foot_material">
        <color
          rgba="1 0.341176470588235 0.56078431372549 1" />
      </material>
    </visual>
    <collision>
      <origin
        xyz="0 0 0"
        rpy="0 0 0" />
      <geometry>
        <sphere radius="0.022" />
      </geometry>
    </collision>
  </link>
  <joint
    name="FL_foot_joint"
    type="fixed">
    <origin
      xyz="0 0 -0.181256552442634"
      rpy="0 0 0" />
    <parent
      link="FL_calf" />
    <child
      link="FL_foot" />
    <dont_collapse/>
  </joint>
  <link
    name="FR_hip">
    <inertial>
      <origin
        xyz="0.0586708362293078 -0.00172067827101646 8.04098946586701E-05"
        rpy="0 0 0" />
      <mass
        value="0.230146330118094" />
      <inertia
        ixx="0.000145714252035463"
        ixy="1.35495978782589E-07"
        ixz="3.3318802371418E-07"
        iyy="0.000246238315405917"
        iyz="-2.59322004390303E-08"
        izz="0.000128357183764394" />
    </inertial>
    <visual>
      <origin
        xyz="0 0 0"
        rpy="0 0 0" />
      <geometry>
        <mesh
          filename="package://dog_urdf/meshes/FR_hip.STL" />
      </geometry>
      <material
        name="body_material">
        <color
          rgba="0.792156862745098 0.819607843137255 0.933333333333333 1" />
      </material>
    </visual>
    <collision>
      <origin
        xyz="0.03 0 0"
        rpy="0 1.5708 0" />
      <geometry>
        <cylinder radius="0.025" length="0.06" />
      </geometry>
    </collision>
  </link>
  <joint
    name="FR_hip_joint"
    type="revolute">
    <origin
      xyz="0.1426 -0.046513 0"
      rpy="0 0 0" />
    <parent
      link="base_link" />
    <child
      link="FR_hip" />
    <axis
      xyz="-1 0 0" />
    <dynamics damping="0.0" friction="0.0"/>
    <limit
        lower="-0.5"
        upper="0.5"
        effort="40"
        velocity="12" />
  </joint>
  <link
    name="FR_thigh">
    <inertial>
      <origin
        xyz="-3.04126993064119E-05 -0.0530216135200461 -0.0127566141119383"
        rpy="0 0 0" />
      <mass
        value="0.978596689740029" />
      <inertia
        ixx="0.000999824561145867"
        ixy="-2.53314197794912E-07"
        ixz="6.77603302787856E-07"
        iyy="0.00143499535680593"
        iyz="1.56862595632765E-05"
        izz="0.000773011521758588" />
    </inertial>
    <visual>
      <origin
        xyz="0 0 0"
        rpy="0 0 0" />
      <geometry>
        <mesh
          filename="package://dog_urdf/meshes/FR_thigh.STL" />
      </geometry>
      <material
        name="body_material">
        <color
          rgba="0.792156862745098 0.819607843137255 0.933333333333333 1" />
      </material>
    </visual>
    <collision>
      <origin
        xyz="0 -0.055 -0.09"
        rpy="0 -0.35 0" />
      <geometry>
        <cylinder radius="0.03" length="0.18" />
      </geometry>
    </collision>
  </link>
  <joint
    name="FR_thigh_joint"
    type="revolute">
    <origin
      xyz="0.0645133382530963 -0.0204367742981588 0"
      rpy="0 0 0" />
    <parent
      link="FR_hip" />
    <child
      link="FR_thigh" />
    <axis
      xyz="0 1 0" />
    <dynamics damping="0.0" friction="0.0"/>
    <limit
        lower="-1.90"
        upper="1.92"
        effort="55"
        velocity="14" />
  </joint>
  <link
    name="FR_calf">
    <inertial>
      <origin
        xyz="-3.05292895772663E-05 9.36885009465982E-05 -0.067081967022727"
        rpy="0 0 0" />
      <mass
        value="0.174854579981967" />
      <inertia
        ixx="0.000347514079997906"
        ixy="9.59597363222394E-08"
        ixz="3.10971733237232E-07"
        iyy="0.00036351836127092"
        iyz="1.28911233952038E-06"
        izz="2.29103709558955E-05" />
    </inertial>
    <visual>
      <origin
        xyz="0 0 0"
        rpy="0 0 0" />
      <geometry>
        <mesh
          filename="package://dog_urdf/meshes/FR_calf.STL" />
      </geometry>
      <material
        name="body_material">
        <color
          rgba="0.792156862745098 0.819607843137255 0.933333333333333 1" />
      </material>
    </visual>
    <collision>
      <origin
        xyz="0 0 -0.09"
        rpy="0 0 0" />
      <geometry>
        <cylinder radius="0.022" length="0.18" />
      </geometry>
    </collision>
  </link>
  <joint
    name="FR_calf_joint"
    type="revolute">
    <origin
      xyz="-1.21873416425722E-05 -0.0922 -0.1800005355847"
      rpy="0 0 0" />
    <parent
      link="FR_thigh" />
    <child
      link="FR_calf" />
    <axis
      xyz="0 1 0" />
    <dynamics damping="0.0" friction="0.0"/>
    <limit
        lower="-2.80"
        upper="-0.28"
        effort="55"
        velocity="14" />
  </joint>
  <link
    name="FR_foot">
    <inertial>
      <origin
        xyz="-3.03153155911673E-08 -3.64430707833208E-13 0.0047414283842287"
        rpy="0 0 0" />
      <mass
        value="0.0179075406761492" />
      <inertia
        ixx="1.9964536174572E-06"
        ixy="-1.49762941259772E-11"
        ixz="6.09491739153637E-12"
        iyy="3.20707388303328E-06"
        iyz="-1.94066194464282E-16"
        izz="2.94967483562758E-06" />
    </inertial>
    <visual>
      <origin
        xyz="0 0 0"
        rpy="0 0 0" />
      <geometry>
        <mesh
          filename="package://dog_urdf/meshes/FR_foot.STL" />
      </geometry>
      <material
        name="foot_material">
        <color
          rgba="1 0.341176470588235 0.56078431372549 1" />
      </material>
    </visual>
    <collision>
      <origin
        xyz="0 0 0"
        rpy="0 0 0" />
      <geometry>
        <sphere radius="0.022" />
      </geometry>
    </collision>
  </link>
  <joint
    name="FR_foot_joint"
    type="fixed">
    <origin
      xyz="0 0 -0.181256552442636"
      rpy="0 0 0" />
    <parent
      link="FR_calf" />
    <child
      link="FR_foot" />
    <dont_collapse/>
  </joint>
  <link
    name="RL_hip">
    <inertial>
      <origin
        xyz="-0.0586708362289704 0.00172067827077711 8.04098945089288E-05"
        rpy="0 0 0" />
      <mass
        value="0.230146330113268" />
      <inertia
        ixx="0.000145714252035152"
        ixy="1.35495978608697E-07"
        ixz="-3.33188023368129E-07"
        iyy="0.000246238315405198"
        iyz="2.59322005633722E-08"
        izz="0.000128357183763865" />
    </inertial>
    <visual>
      <origin
        xyz="0 0 0"
        rpy="0 0 0" />
      <geometry>
        <mesh
          filename="package://dog_urdf/meshes/RL_hip.STL" />
      </geometry>
      <material
        name="body_material">
        <color
          rgba="0.792156862745098 0.819607843137255 0.933333333333333 1" />
      </material>
    </visual>
    <collision>
      <origin
        xyz="-0.03 0 0"
        rpy="0 1.5708 0" />
      <geometry>
        <cylinder radius="0.025" length="0.06" />
      </geometry>
    </collision>
  </link>
  <joint
    name="RL_hip_joint"
    type="revolute">
    <origin
      xyz="-0.1426 0.046513 0"
      rpy="0 0 0" />
    <parent
      link="base_link" />
    <child
      link="RL_hip" />
    <axis
      xyz="1 0 0" />
    <dynamics damping="0.0" friction="0.0"/>
    <limit
        lower="-0.5"
        upper="0.5"
        effort="40"
        velocity="12" />
  </joint>
  <link
    name="RL_thigh">
    <inertial>
      <origin
        xyz="3.04126992746734E-05 0.0530216135200473 -0.0127566141119536"
        rpy="0 0 0" />
      <mass
        value="0.978596689741073" />
      <inertia
        ixx="0.000999824561145886"
        ixy="-2.53314197932174E-07"
        ixz="-6.77603302799857E-07"
        iyy="0.00143499535680685"
        iyz="-1.56862595632812E-05"
        izz="0.000773011521759527" />
    </inertial>
    <visual>
      <origin
        xyz="0 0 0"
        rpy="0 0 0" />
      <geometry>
        <mesh
          filename="package://dog_urdf/meshes/RL_thigh.STL" />
      </geometry>
      <material
        name="body_material">
        <color
          rgba="0.792156862745098 0.819607843137255 0.933333333333333 1" />
      </material>
    </visual>
    <collision>
      <origin
        xyz="0 0.055 -0.09"
        rpy="0 0.35 0" />
      <geometry>
        <cylinder radius="0.03" length="0.18" />
      </geometry>
    </collision>
  </link>
  <joint
    name="RL_thigh_joint"
    type="revolute">
    <origin
      xyz="-0.0645133382530961 0.0204367742981585 0"
      rpy="0 0 0" />
    <parent
      link="RL_hip" />
    <child
      link="RL_thigh" />
    <axis
      xyz="0 1 0" />
    <dynamics damping="0.0" friction="0.0"/>
    <limit
        lower="-1.90"
        upper="1.92"
        effort="55"
        velocity="14" />
  </joint>
  <link
    name="RL_calf">
    <inertial>
      <origin
        xyz="-3.13871287594969E-05 9.36885016845218E-05 -0.0670819666251215"
        rpy="0 0 0" />
      <mass
        value="0.17485457993416" />
      <inertia
        ixx="0.000347514071950219"
        ixy="9.59762214653054E-08"
        ixz="3.15122744417991E-07"
        iyy="0.000363518361226421"
        iyz="1.28911111228658E-06"
        izz="2.29103789594419E-05" />
    </inertial>
    <visual>
      <origin
        xyz="0 0 0"
        rpy="0 0 0" />
      <geometry>
        <mesh
          filename="package://dog_urdf/meshes/RL_calf.STL" />
      </geometry>
      <material
        name="body_material">
        <color
          rgba="0.792156862745098 0.819607843137255 0.933333333333333 1" />
      </material>
    </visual>
    <collision>
      <origin
        xyz="0 0 -0.09"
        rpy="0 0 0" />
      <geometry>
        <cylinder radius="0.022" length="0.18" />
      </geometry>
    </collision>
  </link>
  <joint
    name="RL_calf_joint"
    type="revolute">
    <origin
      xyz="1.21873416414897E-05 0.0922000000000003 -0.180000535584701"
      rpy="0 0 0" />
    <parent
      link="RL_thigh" />
    <child
      link="RL_calf" />
    <axis
      xyz="0 1 0" />
    <dynamics damping="0.0" friction="0.0"/>
    <limit
        lower="-2.80"
        upper="-0.28"
        effort="55"
        velocity="14" />
  </joint>
  <link
    name="RL_foot">
    <inertial>
      <origin
        xyz="3.03161081238734E-08 -2.64765639967912E-13 0.00474142838422875"
        rpy="0 0 0" />
      <mass
        value="0.0179075406761493" />
      <inertia
        ixx="1.9964536174572E-06"
        ixy="-1.49762941286607E-11"
        ixz="-6.09469903773559E-12"
        iyy="3.20707388303329E-06"
        iyz="-1.11568199900604E-17"
        izz="2.9496748356276E-06" />
    </inertial>
    <visual>
      <origin
        xyz="0 0 0"
        rpy="0 0 0" />
      <geometry>
        <mesh
          filename="package://dog_urdf/meshes/RL_foot.STL" />
      </geometry>
      <material
        name="foot_material">
        <color
          rgba="1 0.341176470588235 0.56078431372549 1" />
      </material>
    </visual>
    <collision>
      <origin
        xyz="0 0 0"
        rpy="0 0 0" />
      <geometry>
        <sphere radius="0.022" />
      </geometry>
    </collision>
  </link>
  <joint
    name="RL_foot_joint"
    type="fixed">
    <origin
      xyz="0 0 -0.181256552442636"
      rpy="0 0 0" />
    <parent
      link="RL_calf" />
    <child
      link="RL_foot" />
    <dont_collapse/>
  </joint>
  <link
    name="RR_hip">
    <inertial>
      <origin
        xyz="-0.0586708362293077 -0.00174712967469903 -7.87954214898356E-05"
        rpy="0 0 0" />
      <mass
        value="0.230146330118099" />
      <inertia
        ixx="0.000145714252035464"
        ixy="-1.35495978782578E-07"
        ixz="3.33188023714117E-07"
        iyy="0.000246238315405923"
        iyz="2.59322004390727E-08"
        izz="0.000128357183764399" />
    </inertial>
    <visual>
      <origin
        xyz="0 0 0"
        rpy="0 0 0" />
      <geometry>
        <mesh
          filename="package://dog_urdf/meshes/RR_hip.STL" />
      </geometry>
      <material
        name="body_material">
        <color
          rgba="0.792156862745098 0.819607843137255 0.933333333333333 1" />
      </material>
    </visual>
    <collision>
      <origin
        xyz="-0.03 0 0"
        rpy="0 1.5708 0" />
      <geometry>
        <cylinder radius="0.025" length="0.06" />
      </geometry>
    </collision>
  </link>
  <joint
    name="RR_hip_joint"
    type="revolute">
    <origin
      xyz="-0.1426 -0.0464867742981584 0"
      rpy="0 0 0" />
    <parent
      link="base_link" />
    <child
      link="RR_hip" />
    <axis
      xyz="-1 0 0" />
    <dynamics damping="0.0" friction="0.0"/>
    <limit
        lower="-0.5"
        upper="0.5"
        effort="40"
        velocity="12" />
  </joint>
  <link
    name="RR_thigh">
    <inertial>
      <origin
        xyz="-3.9613059413246E-06 -0.0530216135200264 -0.0127549994696267"
        rpy="0 0 0" />
      <mass
        value="0.978596689739478" />
      <inertia
        ixx="0.000999824561145864"
        ixy="-2.53314197778766E-07"
        ixz="6.77603302799409E-07"
        iyy="0.00143499535680589"
        iyz="1.56862595632762E-05"
        izz="0.000773011521758535" />
    </inertial>
    <visual>
      <origin
        xyz="0 0 0"
        rpy="0 0 0" />
      <geometry>
        <mesh
          filename="package://dog_urdf/meshes/RR_thigh.STL" />
      </geometry>
      <material
        name="body_material">
        <color
          rgba="0.792156862745098 0.819607843137255 0.933333333333333 1" />
      </material>
    </visual>
    <collision>
      <origin
        xyz="0 -0.055 -0.09"
        rpy="0 -0.35 0" />
      <geometry>
        <cylinder radius="0.03" length="0.18" />
      </geometry>
    </collision>
  </link>
  <joint
    name="RR_thigh_joint"
    type="revolute">
    <origin
      xyz="-0.0645133382530962 -0.0204632257018415 0"
      rpy="0 0 0" />
    <parent
      link="RR_hip" />
    <child
      link="RR_thigh" />
    <axis
      xyz="0 1 0" />
    <dynamics damping="0.0" friction="0.0"/>
    <limit
        lower="-1.90"
        upper="1.92"
        effort="55"
        velocity="14" />
  </joint>
  <link
    name="RR_calf">
    <inertial>
      <origin
        xyz="-3.05292895770859E-05 9.36885009470423E-05 -0.0670819670227266"
        rpy="0 0 0" />
      <mass
        value="0.174854579981966" />
      <inertia
        ixx="0.000347514079997903"
        ixy="9.59597363222406E-08"
        ixz="3.10971733237251E-07"
        iyy="0.000363518361270917"
        iyz="1.28911233952033E-06"
        izz="2.29103709558954E-05" />
    </inertial>
    <visual>
      <origin
        xyz="0 0 0"
        rpy="0 0 0" />
      <geometry>
        <mesh
          filename="package://dog_urdf/meshes/RR_calf.STL" />
      </geometry>
      <material
        name="body_material">
        <color
          rgba="0.792156862745098 0.819607843137255 0.933333333333333 1" />
      </material>
    </visual>
    <collision>
      <origin
        xyz="0 0 -0.09"
        rpy="0 0 0" />
      <geometry>
        <cylinder radius="0.022" length="0.18" />
      </geometry>
    </collision>
  </link>
  <joint
    name="RR_calf_joint"
    type="revolute">
    <origin
      xyz="1.42640517169501E-05 -0.0922000000000003 -0.179998920942402"
      rpy="0 0 0" />
    <parent
      link="RR_thigh" />
    <child
      link="RR_calf" />
    <axis
      xyz="0 1 0" />
    <dynamics damping="0.0" friction="0.0"/>
    <limit
        lower="-2.80"
        upper="-0.28"
        effort="55"
        velocity="14" />
  </joint>
  <link
    name="RR_foot">
    <inertial>
      <origin
        xyz="-3.03153156466784E-08 -3.64319685530745E-13 0.00474142838422886"
        rpy="0 0 0" />
      <mass
        value="0.0179075406761493" />
      <inertia
        ixx="1.99645361745721E-06"
        ixy="-1.49762941295088E-11"
        ixz="6.09491740220682E-12"
        iyy="3.20707388303331E-06"
        iyz="-1.9406683628723E-16"
        izz="2.9496748356276E-06" />
    </inertial>
    <visual>
      <origin
        xyz="0 0 0"
        rpy="0 0 0" />
      <geometry>
        <mesh
          filename="package://dog_urdf/meshes/RR_foot.STL" />
      </geometry>
      <material
        name="foot_material">
        <color
          rgba="1 0.341176470588235 0.56078431372549 1" />
      </material>
    </visual>
    <collision>
      <origin
        xyz="0 0 0"
        rpy="0 0 0" />
      <geometry>
        <sphere radius="0.022" />
      </geometry>
    </collision>
  </link>
  <joint
    name="RR_foot_joint"
    type="fixed">
    <origin
      xyz="0 0 -0.181256552442637"
      rpy="0 0 0" />
    <parent
      link="RR_calf" />
    <child
      link="RR_foot" />
    <dont_collapse/>
  </joint>

  <!-- Camera (RealSense D435) mount -->
  <link name="camera_link"/>
  <joint name="camera_joint" type="fixed">
    <parent link="base_link"/>
    <child link="camera_link"/>
    <origin xyz="0.15 0 0.12" rpy="0 0.5236 0"/>
  </joint>

  <gazebo reference="FL_foot"><mu1>1.0</mu1><mu2>1.0</mu2><kp>20000.0</kp><kd>500.0</kd><minDepth>0.001</minDepth><maxVel>0.5</maxVel></gazebo>
  <gazebo reference="FR_foot"><mu1>1.0</mu1><mu2>1.0</mu2><kp>20000.0</kp><kd>500.0</kd><minDepth>0.001</minDepth><maxVel>0.5</maxVel></gazebo>
  <gazebo reference="RL_foot"><mu1>1.0</mu1><mu2>1.0</mu2><kp>20000.0</kp><kd>500.0</kd><minDepth>0.001</minDepth><maxVel>0.5</maxVel></gazebo>
  <gazebo reference="RR_foot"><mu1>1.0</mu1><mu2>1.0</mu2><kp>20000.0</kp><kd>500.0</kd><minDepth>0.001</minDepth><maxVel>0.5</maxVel></gazebo>

  <ros2_control name="gazebo_system" type="system">
    <hardware><plugin>gazebo_ros2_control/GazeboSystem</plugin></hardware>
    <joint name="FL_hip_joint"><command_interface name="position"/><state_interface name="position"/><state_interface name="velocity"/></joint>
    <joint name="FL_thigh_joint"><command_interface name="position"/><state_interface name="position"/><state_interface name="velocity"/></joint>
    <joint name="FL_calf_joint"><command_interface name="position"/><state_interface name="position"/><state_interface name="velocity"/></joint>
    <joint name="FR_hip_joint"><command_interface name="position"/><state_interface name="position"/><state_interface name="velocity"/></joint>
    <joint name="FR_thigh_joint"><command_interface name="position"/><state_interface name="position"/><state_interface name="velocity"/></joint>
    <joint name="FR_calf_joint"><command_interface name="position"/><state_interface name="position"/><state_interface name="velocity"/></joint>
    <joint name="RL_hip_joint"><command_interface name="position"/><state_interface name="position"/><state_interface name="velocity"/></joint>
    <joint name="RL_thigh_joint"><command_interface name="position"/><state_interface name="position"/><state_interface name="velocity"/></joint>
    <joint name="RL_calf_joint"><command_interface name="position"/><state_interface name="position"/><state_interface name="velocity"/></joint>
    <joint name="RR_hip_joint"><command_interface name="position"/><state_interface name="position"/><state_interface name="velocity"/></joint>
    <joint name="RR_thigh_joint"><command_interface name="position"/><state_interface name="position"/><state_interface name="velocity"/></joint>
    <joint name="RR_calf_joint"><command_interface name="position"/><state_interface name="position"/><state_interface name="velocity"/></joint>
  </ros2_control>
  <gazebo>
    <plugin name="gazebo_ros2_control" filename="libgazebo_ros2_control.so">
      <parameters>__CONTROLLER_YAML__</parameters>
    </plugin>
  </gazebo>

  <gazebo reference="base_link">
    <sensor type="imu" name="imu_sensor">
      <always_on>true</always_on>
      <update_rate>200</update_rate>
      <imu>
        <angular_velocity>
          <x><noise type="gaussian" stddev="0.01"/></x>
          <y><noise type="gaussian" stddev="0.01"/></y>
          <z><noise type="gaussian" stddev="0.01"/></z>
        </angular_velocity>
        <linear_acceleration>
          <x><noise type="gaussian" stddev="0.1"/></x>
          <y><noise type="gaussian" stddev="0.1"/></y>
          <z><noise type="gaussian" stddev="0.1"/></z>
        </linear_acceleration>
      </imu>
      <plugin name="gazebo_ros_imu_sensor" filename="libgazebo_ros_imu_sensor.so">
        <ros>
          <namespace>odin1</namespace>
          <remapping>~/out:=imu</remapping>
        </ros>
      </plugin>
    </sensor>
  </gazebo>

  <gazebo reference="base_link">
    <sensor type="depth" name="camera_depth_sensor">
      <always_on>true</always_on>
      <update_rate>30</update_rate>
      <pose>0.15 0 0.12 0 0.5236 0</pose>
      <camera name="camera_depth_camera">
        <horizontal_fov>1.51844</horizontal_fov>
        <image>
          <width>848</width>
          <height>480</height>
          <format>R8G8B8</format>
        </image>
        <clip>
          <near>0.1</near>
          <far>10.0</far>
        </clip>
      </camera>
      <plugin name="camera_depth_plugin" filename="libgazebo_ros_camera.so">
        <ros>
          <namespace>camera</namespace>
          <argument>image_raw:=depth/image_rect_raw</argument>
          <argument>camera_info:=depth/camera_info</argument>
        </ros>
        <camera_name>camera_depth</camera_name>
        <frame_name>camera_depth_optical_frame</frame_name>
        <hack_baseline>0.07</hack_baseline>
      </plugin>
    </sensor>
  </gazebo>

  <link name="camera_depth_optical_frame"/>
  <joint name="camera_depth_joint" type="fixed">
    <parent link="base_link"/>
    <child link="camera_depth_optical_frame"/>
    <origin xyz="0.15 0 0.12" rpy="-1.5707963 0 -1.5707963"/>
  </joint>

</robot>
